Process Process-2:
Traceback (most recent call last):
  File "/opt/conda/lib/python3.8/site-packages/templateflow/api.py", line 201, in _datalad_get
    api.get(filepath, dataset=str(TF_LAYOUT.root))
  File "/opt/conda/lib/python3.8/site-packages/datalad/interface/utils.py", line 484, in eval_func
    return return_func(generator_func)(*args, **kwargs)
  File "/opt/conda/lib/python3.8/site-packages/datalad/interface/utils.py", line 476, in return_func
    results = list(results)
  File "/opt/conda/lib/python3.8/site-packages/datalad/interface/utils.py", line 461, in generator_func
    raise IncompleteResultsError(
datalad.support.exceptions.IncompleteResultsError: Command did not complete successfully. 1 failed:
[{'action': 'get',
  'annexkey': 'MD5E-s720487--c1390ecd78b0f3bd7600dd655bbcf413.surf.gii',
  'error_message': 'RuntimeError(Failed to fetch any archive containing '
                   'MD5E-s720487--c1390ecd78b0f3bd7600dd655bbcf413.surf.gii. '
                   'Tried: '
                   "['MD5E-s15799461--942684a9c74fd10bd8f91914ca42930c.zip'])\n"
                   'RuntimeError(Failed to fetch any archive containing '
                   'MD5E-s720487--c1390ecd78b0f3bd7600dd655bbcf413.surf.gii. '
                   'Tried: '
                   "['MD5E-s15799461--942684a9c74fd10bd8f91914ca42930c.zip', "
                   "'MD5E-s15799461--942684a9c74fd10bd8f91914ca42930c.zip'])\n"
                   'RuntimeError(Failed to fetch any archive containing '
                   'MD5E-s720487--c1390ecd78b0f3bd7600dd655bbcf413.surf.gii. '
                   'Tried: '
                   "['MD5E-s15799461--942684a9c74fd10bd8f91914ca42930c.zip', "
                   "'MD5E-s15799461--942684a9c74fd10bd8f91914ca42930c.zip'])",
  'path': '/scratch1/03201/jbwexler/openneuro_derivatives/derivatives/fmriprep/ds002422-fmriprep/sourcedata/templateflow/tpl-fsLR/tpl-fsLR_space-fsaverage_hemi-L_den-32k_sphere.surf.gii',
  'refds': '/scratch1/03201/jbwexler/openneuro_derivatives/derivatives/fmriprep/ds002422-fmriprep/sourcedata/templateflow',
  'status': 'error',
  'type': 'file'}]

During handling of the above exception, another exception occurred:

Traceback (most recent call last):
  File "/opt/conda/lib/python3.8/multiprocessing/process.py", line 315, in _bootstrap
    self.run()
  File "/opt/conda/lib/python3.8/multiprocessing/process.py", line 108, in run
    self._target(*self._args, **self._kwargs)
  File "/opt/conda/lib/python3.8/site-packages/fmriprep/cli/workflow.py", line 118, in build_workflow
    retval["workflow"] = init_fmriprep_wf()
  File "/opt/conda/lib/python3.8/site-packages/fmriprep/workflows/base.py", line 85, in init_fmriprep_wf
    single_subject_wf = init_single_subject_wf(subject_id)
  File "/opt/conda/lib/python3.8/site-packages/fmriprep/workflows/base.py", line 370, in init_single_subject_wf
    func_preproc_wf = init_func_preproc_wf(bold_file, has_fieldmap=has_fieldmap)
  File "/opt/conda/lib/python3.8/site-packages/fmriprep/workflows/bold/base.py", line 868, in init_func_preproc_wf
    bold_grayords_wf = init_bold_grayords_wf(
  File "/opt/conda/lib/python3.8/site-packages/fmriprep/workflows/bold/resampling.py", line 798, in init_bold_grayords_wf
    resample.inputs.new_sphere = [
  File "/opt/conda/lib/python3.8/site-packages/fmriprep/workflows/bold/resampling.py", line 800, in <listcomp>
    tf.get(
  File "/opt/conda/lib/python3.8/site-packages/templateflow/conf/__init__.py", line 31, in wrapper
    return func(*args, **kwargs)
  File "/opt/conda/lib/python3.8/site-packages/templateflow/api.py", line 73, in get
    _datalad_get(filepath)
  File "/opt/conda/lib/python3.8/site-packages/templateflow/api.py", line 203, in _datalad_get
    if exc.failed[0]["message"] == "path not associated with any dataset":
KeyError: 'message'
