Process Process-2:
Traceback (most recent call last):
  File "/opt/conda/lib/python3.8/site-packages/templateflow/api.py", line 201, in _datalad_get
    api.get(filepath, dataset=str(TF_LAYOUT.root))
  File "/opt/conda/lib/python3.8/site-packages/datalad/interface/utils.py", line 484, in eval_func
    return return_func(generator_func)(*args, **kwargs)
  File "/opt/conda/lib/python3.8/site-packages/datalad/interface/utils.py", line 476, in return_func
    results = list(results)
  File "/opt/conda/lib/python3.8/site-packages/datalad/interface/utils.py", line 461, in generator_func
    raise IncompleteResultsError(
datalad.support.exceptions.IncompleteResultsError: Command did not complete successfully. 1 failed:
[{'action': 'get',
  'annexkey': 'MD5E-s1751209--e401c5b0311864c4c2f3625c9617374f.nii.gz',
  'error_message': 'git-annex: '
                   '.git/annex/tmp/MD5E-s1751209--e401c5b0311864c4c2f3625c9617374f.nii.gz: '
                   'removeLink: does not exist (No such file or directory)',
  'path': '/scratch1/03201/jbwexler/openneuro_derivatives/derivatives/fmriprep/ds002422-fmriprep/sourcedata/templateflow/tpl-MNI152NLin2009cAsym/tpl-MNI152NLin2009cAsym_res-02_desc-fMRIPrep_boldref.nii.gz',
  'refds': '/scratch1/03201/jbwexler/openneuro_derivatives/derivatives/fmriprep/ds002422-fmriprep/sourcedata/templateflow',
  'status': 'error',
  'type': 'file'}]

During handling of the above exception, another exception occurred:

Traceback (most recent call last):
  File "/opt/conda/lib/python3.8/multiprocessing/process.py", line 315, in _bootstrap
    self.run()
  File "/opt/conda/lib/python3.8/multiprocessing/process.py", line 108, in run
    self._target(*self._args, **self._kwargs)
  File "/opt/conda/lib/python3.8/site-packages/fmriprep/cli/workflow.py", line 118, in build_workflow
    retval["workflow"] = init_fmriprep_wf()
  File "/opt/conda/lib/python3.8/site-packages/fmriprep/workflows/base.py", line 85, in init_fmriprep_wf
    single_subject_wf = init_single_subject_wf(subject_id)
  File "/opt/conda/lib/python3.8/site-packages/fmriprep/workflows/base.py", line 370, in init_single_subject_wf
    func_preproc_wf = init_func_preproc_wf(bold_file, has_fieldmap=has_fieldmap)
  File "/opt/conda/lib/python3.8/site-packages/fmriprep/workflows/bold/base.py", line 438, in init_func_preproc_wf
    initial_boldref_wf = init_bold_reference_wf(
  File "/opt/conda/lib/python3.8/site-packages/niworkflows/func/util.py", line 192, in init_bold_reference_wf
    enhance_and_skullstrip_bold_wf = init_enhance_and_skullstrip_bold_wf(
  File "/opt/conda/lib/python3.8/site-packages/niworkflows/func/util.py", line 447, in init_enhance_and_skullstrip_bold_wf
    bold_template = get_template(
  File "/opt/conda/lib/python3.8/site-packages/templateflow/conf/__init__.py", line 31, in wrapper
    return func(*args, **kwargs)
  File "/opt/conda/lib/python3.8/site-packages/templateflow/api.py", line 73, in get
    _datalad_get(filepath)
  File "/opt/conda/lib/python3.8/site-packages/templateflow/api.py", line 203, in _datalad_get
    if exc.failed[0]["message"] == "path not associated with any dataset":
KeyError: 'message'
